#VRML_SIM R2018a utf8
PROTO CozmoBotModern [

  field MFVec3f testField [ 0 0 0, 0 0 0 ]

  field SFString advertisementHost "127.0.0.1"

  field SFVec3f translation 0 0 0
  field SFRotation rotation 0 0 1 0
  field SFString name "Cozmo"

  # CVGA Crop:
#  field SFInt32  cameraWidth  400
#  field SFInt32  cameraHeight 296
#  field SFFloat  fieldOfView  1.21

  # QVGA Crop:
  field SFInt32  cameraWidth  320
  field SFInt32  cameraHeight 240
  field SFFloat  fieldOfView  1.04

  # VGA Wide:
#    field SFInt32  cameraWidth  640
#    field SFInt32  cameraHeight 480
#    field SFFloat  fieldOfView  1.21

  field SFBool   hideCameraDisplay FALSE

  field SFFloat headAngle          0
  field SFFloat headAngle_lowLimit -0.4363 # 25 degrees down
  field SFFloat headAngle_highLimit 0.7854 # 45 degrees up

  field SFFloat liftAngle 0
  field SFFloat liftAngle_lowLimit  -0.01  # Should be 0, but Webots needs it to be less than liftAngle
  #field SFFloat liftAngle_highLimit 1.047  # 60 degrees up
  field SFFloat liftAngle_highLimit 1.06

  field SFBool filterLogs FALSE
  field SFString controller "reproController"
  field SFString controllerArgs ""

  field SFColor bodyColor 0.92 0.92 0.8

  # Set to TRUE if you just want to use the model for visualization.
  field SFBool vizMode FALSE

  # Whether or not to enable video
  field SFBool enableVideo TRUE

  # Tread wheel parameters
  field SFFloat frontWheelRadiusM   0.0145
  field SFFloat rearWheelRadiusM    0.01075
  field SFFloat rearWheelDistToFrontWheelM 0.048

  # The number of intermediate wheels to simulate in each tread between the two end wheels.
  field SFInt32 numInterTreadWheels 2

  # Autoconnect to all blocks in world (as if they were paired in flash)
  field SFBool autoConnectToBlocks FALSE

  # Used for animation tests, specify animation to test
  field SFString animationTestName ""
]
{
  Supervisor {
    translation IS translation
    rotation IS rotation
    name IS name

    %{ if not fields.vizMode.value then }%

      # append filter command line parameter if filter is set to TRUE
      %{ if fields.filterLogs.value then }%
        %{ autoArgs=fields.controllerArgs.value .. "--applyLogFilter"}%
      %{ else }%
        %{ autoArgs=fields.controllerArgs.value}%
      %{ end }%

      controller IS controller
      controllerArgs "%{=autoArgs}%"
    %{ else }%
      controller ""
      controllerArgs ""
    %{ end }%

    %{ if not fields.vizMode.value then }%
    boundingObject DEF BODY_SHAPE Group {
      children [
        Transform {
          translation 0 0 0.0142
          children [
            Shape {
              geometry Cylinder {
                height 0.032
                radius 0.014
                subdivision 24
              }
            }
          ]
        }
        Transform {
          translation -0.0278 0 0.0142
          children [
            Shape {
              geometry Box {
                size 0.042 0.035 0.028
              }
            }
          ]
        }
      ] # BODY_SHAPE Group children
    } # BODY_SHAPE Group
    physics Physics {
      density 5000
      # mass 0.17
    }
    %{ end }%

    children [
      CozmoBody {
      }
      CozmoInterWheelBlock {
          translation -0.026 0.023 0.0121
      }
      CozmoInterWheelBlock {
          translation -0.026 -0.023 0.0121
      }
      CozmoLights {
      }

      %{ if not fields.vizMode.value then }%

      # Comms for communicating with blocks
      Emitter {
        name "blockCommsEmitter"
      }

      # There should be a total of MAX_NUM_ACTIVE_OBJECTS (defined in activeObjectTypes.clad) receivers plus a receiver for discovery
      Receiver {
        name "discoveryReceiver"
      }
      Receiver {
        name "blockCommsReceiver0"
      }
      Receiver {
        name "blockCommsReceiver1"
      }
      Receiver {
        name "blockCommsReceiver2"
      }
      Receiver {
        name "blockCommsReceiver3"
      }
      Receiver {
        name "blockCommsReceiver4"
      }

      # Are these still needed?
      GPS {
        name "gps"
      }
      Compass {
        name "compass"
      }
      Transform {
        translation 0 0 0.0012
        rotation 0 1 0 1.5708
        children [
          DistanceSensor {
            name "cliffSensor"
            type "infra-red"
            aperture 0.5
            lookupTable [0   900 0,
                         0.2   0 0]
          }
        ]
      }
      %{ end }%  # vizMode

      Transform {
        translation 0 0 0.0142 # wheel radius
        children [
          %{ if not fields.vizMode.value then }% # ChargeContacts
            Connector {
              translation -0.015 0 -0.013
              rotation 0 1 0 3.14159
              name        "ChargeContact"
              model       "ChargeContact"
              type        "symmetric"
              isLocked    FALSE
              autoLock    FALSE
              distanceTolerance 0.01
              axisTolerance   0.2
              rotationTolerance   1.5708
              numberOfRotations   4
              snap      FALSE
            }
          %{ end }% # ChargeContacts

          DEF HEAD Transform {
            translation -0.013 0 0.0345
            children [
              HingeJoint {
                jointParameters HingeJointParameters {
                  dampingConstant 1
                  position IS headAngle
                  maxStop IS headAngle_highLimit
                  minStop IS headAngle_lowLimit
                  axis 0 -1 0
                }
                %{ if not fields.vizMode.value then }%
                device [
                  RotationalMotor {
                    name "HeadMotor"
                  }
                  PositionSensor {
                    name "HeadMotorPosSensor"
                    resolution 0.001
                  }
                ]
                %{ end }%
                endPoint Solid {
                  children [
                  %{ if not fields.vizMode.value then }%
                  Camera {
                    name "HeadCamera"
                    # Note: 8.8mm to lens face, 5.8mm to PCB mount, optical center = ?
                    translation 0.01752 0 -0.008 # Matches engine definitions
                    #rotation 0.57735 -0.57735 -0.57735 2.0944 # looking straight ahead
                    rotation    0.563430001007340  -0.563430001007340  -0.604229482837223 2.054545429548061 # 4-degree look-down
                    width IS cameraWidth
                    height IS cameraHeight
                    fieldOfView IS fieldOfView
                    near 0.005
                    antiAliasing TRUE
                  }
                  Gyro {
                    name "gyro"
                    translation 0.0058 -0.0135 0

                    # +/- 500 deg/s range expressed by 16-bits
                    # resolution 0.0002663
                  }
                  Accelerometer {
                    name "accel"
                    translation 0.0058 -0.0135 0

                    # +/-2g (+/- 19.62m/s^2) range expressed by 12-bits
                    # resolution 0.00958
                  }
                  Speaker {
                    name "HeadSpeaker"
                  }
                  %{ end }%  #vizMode
                  CozmoHead {
                  }
                  DEF FACE Transform {
                    translation 0.012 0 0
                    children [
                      Transform {
                        translation 0.0037 0 0.0035
                        rotation 1 0 0 1.5708
                        children[
                          Display {
                            name           "face_display"
                            width          128
                            height         64
                            children [
                              Shape {
                                appearance Appearance {
                                  material Material {
                                    diffuseColor 0.0862745 0.0862745 0.0862745
                                    specularColor 0.454902 0.454902 0.454902
                                  }
                                  texture ImageTexture {
                                  }
                                }
                                geometry IndexedFaceSet {
                                  coord Coordinate {
                                    point [
                                      0.0005 0.005 0.01,
                                      0.0005 -0.005 0.01,
                                      0.0005 -0.005 -0.01,
                                      0.0005 0.005 -0.01,
                                    ]
                                  }
                                  texCoord TextureCoordinate {
                                    point [
                                      0 1
                                      0 0
                                      1 0
                                      1 1
                                    ]
                                  }
                                  coordIndex [
                                    0, 1, 2, 3
                                  ]
                                  texCoordIndex [
                                    0, 1, 2, 3
                                  ]
                                }
#                                geometry Box {
#                                  size 0.001 0.012 0.020
#                                }
                              }
                            ]
                          }
                        ]
                      }
                    ]
                  }
                ]
                name "head"

                %{ if not fields.vizMode.value then }%
                boundingObject Box {
                  size 0.030 0.030 0.030
                }
                physics Physics {
                }
                %{ end }%
                }
              }
            ]
          } # DEF HEAD Transform
          DEF BACKPACK Solid {
            name "backpack"
            %{ if not fields.vizMode.value then }%
            boundingObject DEF BACKPACK_GROUP Group {
              children [
                Transform {
                  translation -0.0425 0 0.0213
                  children [
                    Box {
                      size 0.026 0.036 0.034
                    }
                  ]
                }
                Transform {
                  translation -0.0405 0 0.0434
                  rotation 0 1 0 6.1082
                  children [
                    Box {
                      size 0.025 0.036 0.007
                    }
                  ]
                }
                Transform {
                  translation -0.0557 0 0.0344
                  rotation 0 -1 0 1.0471
                  children [
                    Box {
                      size 0.019 0.036 0.007
                    }
                  ]
                }
                Transform {
                  translation -0.0591 0 0.0196
                  rotation 0 -1 0 1.5707
                  children [
                    Box {
                      size 0.019 0.036 0.011
                    }
                  ]
                }
              ]
            } # BACKPACK_GROUP
            physics Physics {
              density 2000
            }
            %{ end }%
          } # BACKPACK Solid

          Track {
            translation 0 0.023 0
            rotation 1 0 0 -1.5707963
            children [
              DEF FRONT_TRACK_WHEEL TrackWheel {
                position 0 0
                radius 0.0145
                children [
                  DEF TRACK_WHEEL_BIG Transform {
                    rotation 1 0 0 1.5707963
                    children [
                      CozmoFrontWheel {
                      }
                    ]
                  }
                ]
              }
              DEF REAR_TRACK_WHEEL TrackWheel {
                position -0.048 0.00375
                radius 0.01075
                children [
                  DEF TRACK_WHEEL_SMALL Transform {
                    rotation 1 0 0 1.5707963
                    children [
                      CozmoBackWheel {
                      }
                    ]
                  }
                ]
              }

            ]
            name "left track"
            contactMaterial "highfriction"

            # The boundingObject is the thing that actually determines the physical shape
            # of the track
            %{ if not fields.vizMode.value then }%
            boundingObject DEF TRACK_BO Group {
              children [
                # Front wheel
                Transform {
                  rotation 1 0 0 -1.5707963
                  children [
                    Cylinder {
                      height 0.01
                      radius %{=fields.frontWheelRadiusM.value}%
                      subdivision 14
                    }
                  ]
                }
                # Create intermediate wheels
                %{ totalRadDistM = (fields.frontWheelRadiusM.value - fields.rearWheelRadiusM.value)
                   distStepM = fields.rearWheelDistToFrontWheelM.value / (fields.numInterTreadWheels.value + 1)
                   radStepM  = totalRadDistM / (fields.numInterTreadWheels.value + 1)
                }%
                %{ if fields.numInterTreadWheels.value > 0 then }%
                  %{ for iw=1,fields.numInterTreadWheels.value do }%

                  Transform {
                    translation %{= iw * distStepM - fields.rearWheelDistToFrontWheelM.value}% %{= totalRadDistM - (iw * radStepM) }% 0
                    rotation 1 0 0 -1.5707963
                    children [
                      Cylinder {
                        height 0.01
                        radius %{= fields.rearWheelRadiusM.value + (iw * radStepM) }%
                        subdivision 14
                      }
                    ]
                  }

                  %{ end }% # for loop
                %{ end }% # intermediate tread wheels

                # Rear wheel
                Transform {
                  translation %{=-fields.rearWheelDistToFrontWheelM.value}% 0.00375 0
                  rotation 1 0 0 -1.5707963
                  children [
                    Cylinder {
                      height 0.01
                      radius %{=fields.rearWheelRadiusM.value}%
                      subdivision 14
                    }
                  ]
                }
              ]
            }
            physics Physics {
            }
            device [
              LinearMotor {
                name "LeftWheelMotor"
              }
              PositionSensor {
                name "LeftWheelMotorPosSensor"
                resolution 0.001
              }
            ]
            %{ end }% # vizmode

            # Shape of tread studs
            animatedGeometry DEF ANIMATED_SHAPE Shape {
              appearance Appearance {
                material Material {
                  diffuseColor 0.141176 0.141176 0.141176
                }
              }
              geometry IndexedFaceSet {
                coord Coordinate {
                  point [
                    -0.00187 0 0.005 -0.00187 0 -0.005 0.00187 0 -0.005 0.00187 0 0.005 -0.00187 -0.000546 0.005 -0.00187 -0.000546 -0.005 0.00187 -0.000546 -0.005 0.00187 -0.000546 0.005 0 0 0.005 -0.00187 0 0 0.00187 0 0 0 0 -0.005 0 0.000675 0.005 0.000665 0 0.005 -0.00187 0 -0.0025 0.00187 0 0.0025 0.000665 0 -0.005 -0.000665 0 0.005 -0.00187 0 0.0025 0.00187 0 -0.0025 -0.000665 0 -0.005 -0.000665 0.000675 0.005 -0.000665 0.000675 -0.005 -0.000665 0 0 0.000665 0 0 0.000665 0 0.0025 -0.000665 0 0.0025 -0.000665 0 -0.0025 0.000665 0 -0.0025 0 0.000675 -0.005 0.000665 0.000675 0.005 0.000665 0.000675 -0.005 0.000665 0.000675 0.0025 0.000665 0.000675 0 -0.000665 0.000675 0.0025 -0.000665 0.000675 0 -0.000665 0.000675 -0.0025 0.000665 0.000675 -0.0025
                  ]
                }
                coordIndex [
                  4, 5, 6, -1, 4, 6, 7, -1, 10, 7 6, -1, 11, 6, 5, -1, 9, 5, 4, -1 8, 4, 7, -1, 19, 16, 28, -1, 37, 29 36, -1, 24, 32, 25, -1, 15, 24, 25, -1 8, 21, 17, -1, 20, 29, 11, -1, 3, 25 13, -1, 26, 9, 18, -1, 17, 18, 0, -1 26, 35, 23, -1, 27, 1, 14, -1, 23, 14 9, -1, 25, 30, 13, -1, 11, 31, 16, -1 13, 12, 8, -1, 10, 28, 24, -1, 27, 22 20, -1, 17, 34, 26, -1, 16, 37, 28, -1 23, 36, 27, -1, 28, 33, 24, -1, 6, 2 19, -1, 10, 15, 7, -1, 6, 19, 10, -1 3, 7, 15, -1, 5, 1, 20, -1, 11, 16 6, -1, 5, 20, 11, -1, 2, 6, 16, -1 4, 0, 18, -1, 9, 14, 5, -1, 4, 18 9, -1, 1, 5, 14, -1, 7, 3, 13, -1 8, 17, 4, -1, 7, 13, 8, -1, 0, 4 17, -1, 19, 2, 16, -1, 34, 21, 12, -1 12, 30, 32, -1, 33, 37, 36, -1, 12, 32 34, -1, 35, 34, 33, -1, 29, 22, 36, -1 36, 35, 33, -1, 32, 33, 34, -1, 31, 29 37, -1, 24, 33, 32, -1, 15, 10, 24, -1 8, 12, 21, -1, 20, 22, 29, -1, 3, 15 25, -1, 26, 23, 9, -1, 17, 26, 18, -1 26, 34, 35, -1, 27, 20, 1, -1, 23, 27 14, -1, 25, 32, 30, -1, 11, 29, 31, -1 13, 30, 12, -1, 10, 19, 28, -1, 27, 36 22, -1, 17, 21, 34, -1, 16, 31, 37, -1 23, 35, 36, -1, 28, 37, 33, -1
                ]
              }
            }
            geometriesCount 47
          }

          Track {
            translation 0 -0.023 0
            rotation 1 0 0 -1.5707963
            children [
              DEF FRONT_TRACK_WHEEL TrackWheel {
                position 0 0
                radius 0.0145
                children [
                  DEF TRACK_WHEEL_BIG Transform {
                    rotation 1 0 0 -1.5707963
                    children [
                      CozmoFrontWheel {
                      }
                    ]
                  }
                ]
              }
              DEF REAR_TRACK_WHEEL TrackWheel {
                position -0.048 0.00375
                radius 0.01075
                children [
                  DEF TRACK_WHEEL_SMALL Transform {
                    rotation 1 0 0 -1.5707963
                    children [
                      CozmoBackWheel {
                      }
                    ]
                  }
                ]
              }
            ]
            name "right track"
            contactMaterial "highfriction"

            %{ if not fields.vizMode.value then }%
            boundingObject USE TRACK_BO
            physics Physics {
            }
            device [
              LinearMotor {
                name "RightWheelMotor"
              }
              PositionSensor {
                name "RightWheelMotorPosSensor"
                resolution 0.001
              }
            ]
            %{ end }%

            animatedGeometry USE ANIMATED_SHAPE
            geometriesCount 47
          }

          DEF LIFT Transform {
            translation -0.041 0 0.0305
            children [
              DEF SHOULDER HingeJoint {
                jointParameters HingeJointParameters {
                  axis 0 -1 0
                  dampingConstant 1
                  position IS liftAngle
                  minStop IS liftAngle_lowLimit
                  maxStop IS liftAngle_highLimit
                }
                %{ if not fields.vizMode.value then }%
                device [
                  RotationalMotor {
                    name "LiftMotor"
                    maxVelocity 30
                    maxTorque 30
                  }
                  PositionSensor {
                    name "LiftMotorPosSensor"
                    resolution 0.005
                  }
                ]
                %{ end }%
                endPoint Solid {
                  name "upper shoulder endpoint"
                  children [
                    CozmoUpperShoulder {
                    }
                    #GRIPPER PLATE
                    Transform {
                      translation 0.065 0 -0.012
                      children [
                        HingeJoint {
                          jointParameters HingeJointParameters {
                            anchor 0 0 0.004
                            axis 0 1 0
                          }
                          endPoint DEF SmallFingerGripper Solid {
                            name "GripperPlate"
                            children [
                              Transform {
                                translation 0.004 0 -0.005
                                children [
                                  CozmoLifter {
                                  }
                                ]
                              }
                              %{ if not fields.vizMode.value then }%
                              Connector {
                                name "gripperConnector"
                                translation 0.0035 0 -0.0145
                                rotation 0 1 0 1.57
                                model "magnetic"
                                distanceTolerance 0.005
                                type "active"
                                isLocked FALSE
                                autoLock TRUE
                                tensileStrength 1
                                shearStrength 1
                              }
                              %{ end }%
                            ] # SmallFingerGripper Children

                            %{ if not fields.vizMode.value then }%
                            boundingObject Transform {
                              translation 0.0 0.0 -0.011
                              children [
                                Shape {
                                  geometry Box {
                                    #size 0.007 0.036 0.05
                                    size 0.007 0.036 0.028
                                  }
                                }
                              ]
                            }
                            contactMaterial "cmat_lift"
                            physics Physics {
                            }
                            %{ end }%
                          }  # SmallFingerGripper Solid
                        } # Hinge Joint
                      ] # Transform children
                    } # Transform

                    DEF LEFT_LIFT_ARM Transform {
                      translation 0.0434 0.0190 -0.00285
                      children [
                        CozmoUpperLeftArm {
                        }
                      ]
                    } # LEFT_LIFT_ARM Transform

                    DEF RIGHT_LIFT_ARM Transform {
                      translation 0.0434 -0.0186 -0.0028
                      children [
                        CozmoUpperRightArm {
                        }
                      ]
                    } # RIGHT_LIFT_ARM Transform

                  ] # endPoint Solid children

                  %{ if not fields.vizMode.value then }%
                  boundingObject Group {
                    children [
                      # Right arm
                      Transform {
                        translation 0.0434 -0.0186 -0.0028
                        children [
                          Shape {
                            geometry IndexedFaceSet {
                              coord Coordinate {
                                point [
                                  -0.042173 -0.001308 0.005694 -0.041727 -0.001215 2e-6 -0.041674 -0.004767 0.000109 -0.042149 -0.004764 0.005598 -0.032747 -0.001218 0.004617 -0.033465 -0.001215 0.000801 -0.033412 -0.004937 0.000588 -0.032595 -0.004875 0.004421 0.005163 0.002335 0.002161 0.004609 0.002206 -0.000313 0.004651 -0.000883 -0.000216 0.00528 -0.000563 0.002681 0.009199 0.002704 0.002161 0.008646 0.002574 -0.000534 0.008687 0.000462 -0.000422 0.009316 0.000592 0.002681 0.006749 -0.000429 -0.000433 0.007378 -0.000178 0.002681 0.007261 0.002527 0.002161 0.006707 0.002397 -0.000447 0.015022 0.003166 0.000845 0.014469 0.003037 -0.002194 0.01451 0.00146 -0.002083 0.015139 0.00161 0.001052 0.016835 0.003322 -3.4e-5 0.01616 0.003192 -0.002984 0.016323 0.001616 -0.00323 0.016952 0.001766 0.000173 0.02001 0.003322 -0.002491 0.018992 0.003312 -0.005641 0.019215 0.001785 -0.006024 0.021286 0.001873 -0.003116 0.012228 0.001421 0.001967 0.012111 0.002935 0.001835 0.011558 0.002805 -0.001039 0.011599 0.001197 -0.000976
                                ]
                              }
                              coordIndex [
                                3, 4, 0, -1, 2, 5, 6, -1, 3, 6 7, -1, 0, 5, 1, -1, 5, 10, 6, -1 7, 10, 11, -1, 4, 9, 5, -1, 4, 11 8, -1, 17, 14, 15, -1, 18, 13, 19, -1 18, 15, 12, -1, 19, 14, 16, -1, 9, 16 10, -1, 8, 17, 18, -1, 8, 19, 9, -1 11, 16, 17, -1, 33, 23, 20, -1, 34, 22 35, -1, 35, 23, 32, -1, 34, 20, 21, -1 22, 27, 23, -1, 21, 24, 25, -1, 20, 27 24, -1, 21, 26, 22, -1, 27, 28, 24, -1 26, 29, 30, -1, 26, 31, 27, -1, 25, 28 29, -1, 12, 34, 13, -1, 15, 35, 32, -1 13, 35, 14, -1, 12, 32, 33, -1, 2, 0 1, -1, 29, 31, 30, -1, 3, 7, 4, -1 2, 1, 5, -1, 3, 2, 6, -1, 0, 4 5, -1, 5, 9, 10, -1, 7, 6, 10, -1 4, 8, 9, -1, 4, 7, 11, -1, 17, 16 14, -1, 18, 12, 13, -1, 18, 17, 15, -1 19, 13, 14, -1, 9, 19, 16, -1, 8, 11 17, -1, 8, 18, 19, -1, 11, 10, 16, -1 33, 32, 23, -1, 34, 21, 22, -1, 35, 22 23, -1, 34, 33, 20, -1, 22, 26, 27, -1 21, 20, 24, -1, 20, 23, 27, -1, 21, 25 26, -1, 27, 31, 28, -1, 26, 25, 29, -1 26, 30, 31, -1, 25, 24, 28, -1, 12, 33 34, -1, 15, 14, 35, -1, 13, 34, 35, -1 12, 15, 32, -1, 2, 3, 0, -1, 29, 28 31, -1
                              ]
                            }
                          }
                        ]
                      }
                      # Left arm
                      Transform {
                        translation 0.0434 0.0190 -0.00285
                        children [
                          Shape {
                            geometry IndexedFaceSet {
                              ccw FALSE
                              coord Coordinate {
                                point [
                                  -0.042173 0.001308 0.005694 -0.041727 0.001215 2e-6 -0.041674 0.004767 0.000109 -0.042149 0.004764 0.005598 -0.032747 0.001218 0.004617 -0.033465 0.001215 0.000801 -0.033412 0.004937 0.000588 -0.032595 0.004875 0.004421 0.005163 -0.002335 0.002161 0.004609 -0.002206 -0.000313 0.004651 0.000883 -0.000216 0.00528 0.000563 0.002681 0.009199 -0.002704 0.002161 0.008646 -0.002574 -0.000534 0.008687 -0.000462 -0.000422 0.009316 -0.000592 0.002681 0.006749 0.000429 -0.000433 0.007378 0.000178 0.002681 0.007261 -0.002527 0.002161 0.006707 -0.002397 -0.000447 0.015022 -0.003166 0.000845 0.014469 -0.003037 -0.002194 0.01451 -0.00146 -0.002083 0.015139 -0.00161 0.001052 0.016835 -0.003322 -3.4e-5 0.01616 -0.003192 -0.002984 0.016323 -0.001616 -0.00323 0.016952 -0.001766 0.000173 0.02001 -0.003322 -0.002491 0.018992 -0.003312 -0.005641 0.019215 -0.001785 -0.006024 0.021286 -0.001873 -0.003116 0.012228 -0.001421 0.001967 0.012111 -0.002935 0.001835 0.011558 -0.002805 -0.001039 0.011599 -0.001197 -0.000976
                                ]
                              }
                              coordIndex [
                                3, 4, 0, -1, 2, 5, 6, -1, 3, 6 7, -1, 0, 5, 1, -1, 5, 10, 6, -1 7, 10, 11, -1, 4, 9, 5, -1, 4, 11 8, -1, 17, 14, 15, -1, 18, 13, 19, -1 18, 15, 12, -1, 19, 14, 16, -1, 9, 16 10, -1, 8, 17, 18, -1, 8, 19, 9, -1 11, 16, 17, -1, 33, 23, 20, -1, 34, 22 35, -1, 35, 23, 32, -1, 34, 20, 21, -1 22, 27, 23, -1, 21, 24, 25, -1, 20, 27 24, -1, 21, 26, 22, -1, 27, 28, 24, -1 26, 29, 30, -1, 26, 31, 27, -1, 25, 28 29, -1, 12, 34, 13, -1, 15, 35, 32, -1 13, 35, 14, -1, 12, 32, 33, -1, 2, 0 1, -1, 29, 31, 30, -1, 3, 7, 4, -1 2, 1, 5, -1, 3, 2, 6, -1, 0, 4 5, -1, 5, 9, 10, -1, 7, 6, 10, -1 4, 8, 9, -1, 4, 7, 11, -1, 17, 16 14, -1, 18, 12, 13, -1, 18, 17, 15, -1 19, 13, 14, -1, 9, 19, 16, -1, 8, 11 17, -1, 8, 18, 19, -1, 11, 10, 16, -1 33, 32, 23, -1, 34, 21, 22, -1, 35, 22 23, -1, 34, 33, 20, -1, 22, 26, 27, -1 21, 20, 24, -1, 20, 23, 27, -1, 21, 25 26, -1, 27, 31, 28, -1, 26, 25, 29, -1 26, 30, 31, -1, 25, 24, 28, -1, 12, 33 34, -1, 15, 14, 35, -1, 13, 34, 35, -1 12, 15, 32, -1, 2, 3, 0, -1, 29, 28 31, -1
                              ]
                            }
                          }
                        ]
                      }
                    ]
                  }
                  contactMaterial "noFriction"
                  physics Physics {
                  }
                  %{ end }%

                } # endPoint Solid
              } # HingeJoint

              # Lower Set of Arms
              DEF LOWER_LIFT Transform {
                translation 0 0 -0.012
                children [
                  CozmoLowerShoulder {
                  }
                  # Lower set of arms
                  # Note these have no motor and will move with the upper set
                  DEF SHOULDER_LOWER HingeJoint {
                    jointParameters HingeJointParameters {
                      anchor 0 0 0.004
                      axis 0 -1 0
                    }
                    endPoint Solid {
                      name "lower shoulder endpoint"
                      children [

                        # Hinge to close mechanical loop back to gripper plate
                        Transform {
                          translation 0.065 0 -0.012
                          children [
                            HingeJoint {
                              jointParameters HingeJointParameters {
                                axis 0 1 0
                              }

                              endPoint SolidReference {
                                solidName "GripperPlate"
                              }
                            }
                          ]
                        }

                        DEF RIGHT_LIFT_ARM_LOWER Transform {
                          translation 0.046 -0.0186 -0.00141
                          children [
                            CozmoLowerRightArm {
                            }
                          ]
                        } # RIGHT_LIFT_ARM_LOWER Transform

                        DEF LEFT_LIFT_ARM_LOWER Transform {
                          translation 0.0459 0.0192 -0.00143
                          children [
                            CozmoLowerLeftArm {
                            }
                          ]
                        } # LEFT_LIFT_ARM_LOWER Transform
                      ] # endPoint Solid Children (lower)

                      %{ if not fields.vizMode.value then }%
                      boundingObject Group {
                        children [
                          # Right arm
                          Transform {
                          translation 0.046 -0.0186 -0.00141
                          children [
                              Shape {
                                geometry IndexedFaceSet {
                                  coord Coordinate {
                                    point [
                                      -0.042841 -0.000964 0.003743 -0.042841 -0.000964 -0.000263 -0.042841 -0.004971 -0.000263 -0.042841 -0.004971 0.003743 -0.029665 -0.001103 0.003605 -0.029665 -0.001103 -0.000124 -0.029665 -0.004832 -0.000124 -0.029665 -0.004832 0.003605 0.003164 0.002296 0.002238 0.003164 0.002296 -0.000943 0.003164 -0.000885 -0.000943 0.003164 -0.000885 0.002238 0.009074 0.002718 0.001402 0.009074 0.002682 -0.001427 0.009467 0.001161 -0.001541 0.009467 0.001161 0.001829 0.015381 0.003362 0.000161 0.015381 0.003326 -0.00423 0.015775 0.001804 -0.004711 0.015775 0.001804 0.000149 0.019056 0.003362 -0.001571 0.018056 0.003326 -0.006581 0.01845 0.001804 -0.006939 0.01945 0.001804 -0.002233 0.021253 0.003362 -0.003562 0.018935 0.003326 -0.007269 0.019054 0.001804 -0.007433 0.021121 0.001804 -0.004224
                                    ]
                                  }
                                  coordIndex [
                                    2, 7, 3, -1, 0, 5, 1, -1, 0, 7 4, -1, 1, 6, 2, -1, 5, 8, 9, -1 4, 11, 8, -1, 5, 10, 6, -1, 6, 11 7, -1, 8, 15, 12, -1, 9, 14, 10, -1 10, 15, 11, -1, 9, 12, 13, -1, 14, 19 15, -1, 13, 16, 17, -1, 15, 16, 12, -1 14, 17, 18, -1, 19, 20, 16, -1, 18, 21 22, -1, 18, 23, 19, -1, 17, 20, 21, -1 22, 25, 26, -1, 22, 27, 23, -1, 21, 24 25, -1, 23, 24, 20, -1, 25, 27, 26, -1 2, 0, 1, -1, 2, 6, 7, -1, 0, 4 5, -1, 0, 3, 7, -1, 1, 5, 6, -1 5, 4, 8, -1, 4, 7, 11, -1, 5, 9 10, -1, 6, 10, 11, -1, 8, 11, 15, -1 9, 13, 14, -1, 10, 14, 15, -1, 9, 8 12, -1, 14, 18, 19, -1, 13, 12, 16, -1 15, 19, 16, -1, 14, 13, 17, -1, 19, 23 20, -1, 18, 17, 21, -1, 18, 22, 23, -1 17, 16, 20, -1, 22, 21, 25, -1, 22, 26 27, -1, 21, 20, 24, -1, 23, 27, 24, -1 25, 24, 27, -1, 2, 3, 0, -1
                                  ]
                                }
                              }
                            ]
                          }
                          # Left arm
                          Transform {
                            translation 0.0459 0.018 -0.00143
                            children [
                              Shape {
                                geometry IndexedFaceSet {
                                  coord Coordinate {
                                    point [
                                      -0.042841 0.002228 0.003743 -0.042841 0.002228 -0.000263 -0.042841 0.006234 -0.000263 -0.042841 0.006234 0.003743 -0.029665 0.002367 0.003605 -0.029665 0.002367 -0.000124 -0.029665 0.006096 -0.000124 -0.029665 0.006096 0.003605 0.003164 -0.001032 0.002238 0.003164 -0.001032 -0.000943 0.003164 0.002149 -0.000943 0.003164 0.002149 0.002238 0.009074 -0.001454 0.001402 0.009074 -0.001419 -0.001427 0.009467 0.000103 -0.001541 0.009467 0.000103 0.001829 0.015381 -0.002098 0.000161 0.015381 -0.002062 -0.00423 0.015775 -0.000541 -0.004711 0.015775 -0.000541 0.000149 0.019056 -0.002098 -0.001571 0.018056 -0.002062 -0.006581 0.01845 -0.000541 -0.006939 0.01945 -0.000541 -0.002233 0.021253 -0.002098 -0.003562 0.018935 -0.002062 -0.007269 0.019054 -0.000541 -0.007433 0.021121 -0.000541 -0.004224
                                    ]
                                  }
                                  coordIndex [
                                    7, 2, 3, -1, 5, 0, 1, -1, 4, 3 0, -1, 2, 5, 1, -1, 5, 8, 4, -1 4, 11, 7, -1, 10, 5, 6, -1, 11, 6 7, -1, 8, 15, 11, -1, 14, 9, 10, -1 15, 10, 11, -1, 9, 12, 8, -1, 19, 14 15, -1, 13, 16, 12, -1, 16, 15, 12, -1 14, 17, 13, -1, 20, 19, 16, -1, 18, 21 17, -1, 23, 18, 19, -1, 17, 20, 16, -1 22, 25, 21, -1, 27, 22, 23, -1, 21, 24 20, -1, 24, 23, 20, -1, 25, 27, 24, -1 0, 2, 1, -1, 7, 6, 2, -1, 5, 4 0, -1, 4, 7, 3, -1, 2, 6, 5, -1 5, 9, 8, -1, 4, 8, 11, -1, 10, 9 5, -1, 11, 10, 6, -1, 8, 12, 15, -1 14, 13, 9, -1, 15, 14, 10, -1, 9, 13 12, -1, 19, 18, 14, -1, 13, 17, 16, -1 16, 19, 15, -1, 14, 18, 17, -1, 20, 23 19, -1, 18, 22, 21, -1, 23, 22, 18, -1 17, 21, 20, -1, 22, 26, 25, -1, 27, 26 22, -1, 21, 25, 24, -1, 24, 27, 23, -1 25, 26, 27, -1, 0, 3, 2, -1
                                  ]
                                }
                              }
                            ]
                          }
                        ]
                      }
                      physics Physics {
                      }
                      %{ end }%
                    } # endPoint Solid (lower)
                  } # DEF SHOULDER_LOWER HingeJoint
                ] # LOWER lift transform children
              } # LOWER lift Transofrm
            ] # LIFT Transform children
          } # Lift Transform
        ] # Wheel RadiusTransform Children
      } # Wheel Radius Transform
    ] # Supervisor children
  } # Supervisor
} # PROTO definition
