#VRML_SIM R2018a utf8
PROTO CozmoBotLegacy [

  field MFVec3f testField [ 0 0 0, 0 0 0 ]

  field SFString advertisementHost "127.0.0.1"

  field SFVec3f translation 0 0 0
  field SFRotation rotation 0 0 1 0
  field SFString name "Cozmo"

  # CVGA Crop:
#  field SFInt32  cameraWidth  400
#  field SFInt32  cameraHeight 296
#  field SFFloat  fieldOfView  1.21

  # QVGA Crop:
  field SFInt32  cameraWidth  320
  field SFInt32  cameraHeight 240
  field SFFloat  fieldOfView  1.04

  # VGA Wide:
#    field SFInt32  cameraWidth  640
#    field SFInt32  cameraHeight 480
#    field SFFloat  fieldOfView  1.21

  field SFBool   hideCameraDisplay FALSE

  field SFFloat headAngle          0
  field SFFloat headAngle_lowLimit -0.4363 # 25 degrees down
  field SFFloat headAngle_highLimit 0.7854 # 45 degrees up

  field SFFloat liftAngle 0
  field SFFloat liftAngle_lowLimit  -0.01  # Should be 0, but Webots needs it to be less than liftAngle
  #field SFFloat liftAngle_highLimit 1.047  # 60 degrees up
  field SFFloat liftAngle_highLimit 1.06

  field SFBool filterLogs FALSE
  field SFString controller "reproController"
  field SFString controllerArgs ""

  field SFColor bodyColor 0.92 0.92 0.8

  # Set to TRUE if you just want to use the model for visualization.
  field SFBool vizMode FALSE

  # Whether or not to enable video
  field SFBool enableVideo TRUE

  # Tread wheel parameters
  field SFFloat frontWheelRadiusM   0.0145
  field SFFloat rearWheelRadiusM    0.01075
  field SFFloat rearWheelDistToFrontWheelM 0.048

  # The number of intermediate wheels to simulate in each tread between the two end wheels.
  field SFInt32 numInterTreadWheels 2

  # Autoconnect to all blocks in world (as if they were paired in flash)
  field SFBool autoConnectToBlocks FALSE

  # Used for animation tests, specify animation to test
  field SFString animationTestName ""
]
{

Supervisor {
  translation IS translation
  rotation IS rotation
  name IS name

  %{ if not fields.vizMode.value then }%

    # append filter command line parameter if filter is set to TRUE
    %{ if fields.filterLogs.value then }%
      %{ autoArgs=fields.controllerArgs.value .. "--applyLogFilter"}%
    %{ else }%
      %{ autoArgs=fields.controllerArgs.value}%
    %{ end }%

    controller IS controller
    controllerArgs "%{=autoArgs}%"
  %{ else }%
    controller ""
    controllerArgs ""
  %{ end }%

  %{ if not fields.vizMode.value then }%
    physics Physics {
      density 0.1  # This value needs to be small for some reason otherwise it starts doing the slow-mo rocking thing
      #mass 0.17 # about 6 ounces
    }
  %{ end }%

  children [

  CozmoBody {}

  CozmoInterWheelBlock {
      translation -0.026 0.023 0.0121
  }
  CozmoInterWheelBlock {
      translation -0.026 -0.023 0.0121
  }

  CozmoLights {}

    Transform {
      translation 0 0 0.0142 # wheel radius
      children [

        %{ if not fields.vizMode.value then }%

        # Comms for communicating with blocks
        Emitter {
          name "blockCommsEmitter"
        }

        # There should be a total of MAX_NUM_ACTIVE_OBJECTS (defined in activeObjectTypes.clad) receivers plus a receiver for discovery
        Receiver {
          name "discoveryReceiver"
        }
        Receiver {
          name "blockCommsReceiver0"
        }
        Receiver {
          name "blockCommsReceiver1"
        }
        Receiver {
          name "blockCommsReceiver2"
        }
        Receiver {
          name "blockCommsReceiver3"
        }
        Receiver {
          name "blockCommsReceiver4"
        }

        # Are these still needed?
        GPS {
          name "gps"
          translation 0 0 0
        }
        Compass {
          name "compass"
        }

        Transform {
          translation 0 0 -0.013
          rotation 0 1 0 1.5708
          children [
            DistanceSensor {
              name "cliffSensor"
              type "infra-red"
              aperture 0.5
              lookupTable [0   900 0,
                           0.2   0 0]
            }
          ]
        }

        %{ end }%  # vizMode

        DEF BODY Solid {
          translation -0.015 0 0
          children [

            %{ if not fields.vizMode.value then }% # ChargeContacts
            Transform {
              translation 0 0 -0.013
              rotation 0 1 0 3.14159
              children [
                Connector {
                  name        "ChargeContact"
                  model       "ChargeContact"
                  type        "symmetric"
                  isLocked    FALSE
                  autoLock    FALSE
                  distanceTolerance 0.01
                  axisTolerance   0.2
                  rotationTolerance   1.5708
                  numberOfRotations   4
                  snap      FALSE
                }
              ]
            }
            %{ end }% # ChargeContacts

          ] # BODY Solid children
          %{ if not fields.vizMode.value then }%
          boundingObject DEF BODY_SHAPE Group {
              children [
                Transform {
                  translation 0.015 0 0
                  children [
                    Shape {
                      geometry Cylinder {
                        height 0.0322
                        radius 0.013
                        subdivision 12
                      }
                    }
                  ]
                }
                Transform {
                  translation -0.015 0 0
                  children [
                    Shape {
                      geometry Cylinder {
                        height 0.0322
                        radius 0.013
                        subdivision 12
                      }
                    }
                  ]
                }
                Shape {
                  geometry Box {
                    size 0.03 0.0322 0.026
                  }
                }

              ] # BODY_SHAPE Group children
            } # BODY_SHAPE Group
          physics Physics {
           density 5000
          }
          %{ end }%
        } # BODY Solid

        DEF HEAD Transform {
          translation -0.013 0 0.0345
          children [
            HingeJoint {
              jointParameters HingeJointParameters {
                dampingConstant 1
                position IS headAngle
                maxStop IS headAngle_highLimit
                minStop IS headAngle_lowLimit
                axis 0 -1 0
              }
              %{ if not fields.vizMode.value then }%
              device [
                RotationalMotor {
                  name "HeadMotor"
                }
                PositionSensor {
                  name "HeadMotorPosSensor"
                  resolution 0.001
                }
              ]
              %{ end }%
              endPoint Solid {
                children [

                %{ if not fields.vizMode.value then }%
                Camera {
                  name "HeadCamera"
                  # Note: 8.8mm to lens face, 5.8mm to PCB mount, optical center = ?
                  translation 0.01752 0 -0.008 # Matches engine definitions
                  #rotation 0.57735 -0.57735 -0.57735 2.0944 # looking straight ahead
                  rotation    0.563430001007340  -0.563430001007340  -0.604229482837223 2.054545429548061 # 4-degree look-down
                  width IS cameraWidth
                  height IS cameraHeight
                  fieldOfView IS fieldOfView
                  near 0.005
                  antiAliasing TRUE
                }
                Gyro {
                  name "gyro"
                  translation 0.0058 -0.0135 0

                  # +/- 500 deg/s range expressed by 16-bits
                  # resolution 0.0002663
                }
                Accelerometer {
                  name "accel"
                  translation 0.0058 -0.0135 0

                  # +/-2g (+/- 19.62m/s^2) range expressed by 12-bits
                  # resolution 0.00958
                }
                %{ end }%  #vizMode

                CozmoHead {}

                DEF FACE Transform {
                  translation 0.012 0 0
                  children [
                    Transform {
                      translation 0.0037 0 0.001
                      rotation 1 0 0 1.5708
                      children[
                        Display {
                          name           "face_display"
                          width          128
                          height         64
                          children [
                            Shape {
                              appearance Appearance {
                                material Material {
                                  diffuseColor 0.0862745 0.0862745 0.0862745
                                  specularColor 0.454902 0.454902 0.454902
                                }
                                texture ImageTexture {
                                }
                              }
                              geometry Box {
                                size 0.001 0.012 0.020
                              }
                            }
                          ]
                        }
                      ]
                    }
                  ]
                }
              ]
              name "head"

              %{ if not fields.vizMode.value then }%
              boundingObject DEF HEAD_SHAPE Group {
                children [
                  Transform {
                    translation 0.012 0 0.012
                    children [
                      DEF HEAD_CAPSULE_WIDTH Shape {
                          geometry Capsule {
                            height 0.03
                            radius 0.005
                          }
                        }
                      ]
                    }

                    Transform {
                      translation 0.012 0 -0.012
                      children [
                        USE HEAD_CAPSULE_WIDTH
                      ]
                    }

                    Transform {
                      translation -0.012 0 0.007
                      children [
                        USE HEAD_CAPSULE_WIDTH
                      ]
                    }

                    Transform {
                      translation -0.012 0 -0.007
                      children [
                        USE HEAD_CAPSULE_WIDTH
                      ]
                    }

                    # Front height capsules
                    Transform {
                      translation 0.012 0.015 0
                      rotation 1 0 0 1.5708
                      children [
                        DEF HEAD_CAPSULE_HEIGHT_FRONT Shape {
                          geometry Capsule {
                            height 0.024
                            radius 0.005
                          }
                        }
                      ]
                    }

                    Transform {
                      translation 0.012 -0.015 0
                      rotation 1 0 0 1.5708
                      children [
                        USE HEAD_CAPSULE_HEIGHT_FRONT
                      ]
                    }

                    # Rear height capsules
                    Transform {
                      translation -0.012 0.015 0
                      rotation 1 0 0 1.5708
                      children [
                        DEF HEAD_CAPSULE_HEIGHT_REAR Shape {
                          geometry Capsule {
                            height 0.014
                            radius 0.005
                          }
                        }
                      ]
                    }

                    Transform {
                      translation -0.012 -0.015 0
                      rotation 1 0 0 1.5708
                      children [
                        USE HEAD_CAPSULE_HEIGHT_REAR
                      ]
                    }

                    # Length-wise capsules
                    Transform {
                      rotation -0.0944316 -0.0944316 0.991043 1.59
                      translation 0.0005 0.015 0.009
                      children [
                        DEF HEAD_CAPSULE_LENGTH Shape {
                          geometry Capsule {
                            height 0.0235
                            radius 0.005
                          }
                        }
                      ]
                    }

                    Transform {
                      rotation 0.0944316 0.0944316 0.991043 1.59
                      translation 0.0005 0.015 -0.009
                      children [
                        USE HEAD_CAPSULE_LENGTH
                      ]
                    }

                    Transform {
                      rotation -0.0944316 -0.0944316 0.991043 1.59 #1.57979
                      translation 0.0005 -0.015 0.009
                      children [
                        USE HEAD_CAPSULE_LENGTH
                      ]
                    }

                    Transform {
                      rotation 0.0944316 0.0944316 0.991043 1.59
                      translation 0.0005 -0.015 -0.009
                      children [
                        USE HEAD_CAPSULE_LENGTH
                      ]
                    }

                  # Head cap (top)
                  Transform {
                    translation 0.0003 0 0.01375
                    rotation 0 -1 0 0.22
                    children [
                      Shape {
                        geometry Box {
                          size 0.024 0.03 0.001
                        }
                      }
                    ]
                  }

                  # Head cap (back)
                  Transform {
                    translation -0.0165 0 0
                    children [
                      Shape {
                        geometry Box {
                          size 0.001 0.03 0.014
                        }
                      }
                    ]
                  }


                ]
              } # End of HEAD_SHAPE
              physics Physics {
                density 1000
              }
              %{ end }%
              }
            }
          ]
        } # DEF HEAD Transform

        DEF BACKPACK Solid {
          translation -0.04 0 0.018

          %{ if not fields.vizMode.value then }%
          boundingObject DEF BACKPACK_GROUP Group {
            children [
              Transform {
                children [
                  Shape {
                    geometry Box {
                    size 0.03 0.03905 0.0206
                    }
                  }
                ]
              }
              Transform {
                translation 0 0 0.0113
                children [
                  Shape {
                    geometry Cylinder {
                      height 0.039
                      radius 0.015
                      subdivision 16
                    }
                  }
                ]
              }
              Transform {
                translation 0 0 -0.0113
                children [
                  Shape {
                    geometry Cylinder {
                      height 0.039
                      radius 0.015
                      subdivision 16
                    }
                  }
                ]
              }
            ]
          } # BACKPACK_GROUP

          physics Physics {
            density 2000
          }
          %{ end }%
        } # BACKPACK Solid

        Track {
          translation 0 0.023 0
          rotation 1 0 0 -1.5707963
          children [

            DEF FRONT_TRACK_WHEEL TrackWheel {
              position 0 0
              radius 0.0145
              children [
                DEF TRACK_WHEEL_BIG Transform {
                  rotation 1 0 0 1.5707963
                  children [
                    CozmoFrontWheel {}
                  ]
                }
              ]
            }

            DEF REAR_TRACK_WHEEL TrackWheel {
              position -0.048 0.00375
              radius 0.01075
              children [
                DEF TRACK_WHEEL_SMALL Transform {
                  rotation 1 0 0 1.5707963
                  children [
                    CozmoBackWheel {}
                  ]
                }
              ]
            }

          ]
          name "left track"
          contactMaterial "highfriction"

          # The boundingObject is the thing that actually determines the physical shape
          # of the track
          %{ if not fields.vizMode.value then }%
          boundingObject DEF TRACK_BO Group {
            children [

              # Front wheel
              Transform {
                translation 0 0 0
                rotation 1 0 0 -1.5707963
                children [
                  Cylinder {
                    height 0.01
                    radius %{=fields.frontWheelRadiusM.value}%
                    subdivision 14
                  }
                ]
              }

              # Create intermediate wheels
              %{ totalRadDistM = (fields.frontWheelRadiusM.value - fields.rearWheelRadiusM.value)
                 distStepM = fields.rearWheelDistToFrontWheelM.value / (fields.numInterTreadWheels.value + 1)
                 radStepM  = totalRadDistM / (fields.numInterTreadWheels.value + 1)
                 if fields.numInterTreadWheels.value > 0 then
                   for iw=1,fields.numInterTreadWheels.value do
              }%

              Transform {
                translation %{= iw * distStepM - fields.rearWheelDistToFrontWheelM.value}% %{= totalRadDistM - (iw * radStepM) }% 0
                rotation 1 0 0 -1.5707963
                children [
                  Cylinder {
                    height 0.01
                    radius %{= fields.rearWheelRadiusM.value + (iw * radStepM) }%
                    subdivision 14
                  }
                ]
              }

              %{ end }% # vizMode
              %{ end }%  # intermediate tread wheels

              # Rear wheel
              Transform {
                translation %{=-fields.rearWheelDistToFrontWheelM.value}% 0.00375 0
                rotation 1 0 0 -1.5707963
                children [
                  Cylinder {
                    height 0.01
                    radius %{=fields.rearWheelRadiusM.value}%
                    subdivision 14
                  }
                ]
              }
            ]
          }
          physics Physics {
          }
          device [
            LinearMotor {
              name "LeftWheelMotor"
            }
            PositionSensor {
              name "LeftWheelMotorPosSensor"
              resolution 0.001
            }
          ]
          %{ end }%

          # Shape of tread studs
          animatedGeometry DEF ANIMATED_SHAPE Shape {
            appearance Appearance {
              material Material {
                diffuseColor 0.141176 0.141176 0.141176
              }
            }
            geometry IndexedFaceSet {
              coord Coordinate {
                point [
                  -0.00187 0 0.005
                  -0.00187 0 -0.005
                  0.00187 0 -0.005
                  0.00187 0 0.005
                  -0.00187 -0.000546 0.005
                  -0.00187 -0.000546 -0.005
                  0.00187 -0.000546 -0.005
                  0.00187 -0.000546 0.005
                  0 0 0.005
                  -0.00187 0 0
                  0.00187 0 0
                  0 0 -0.005
                  0 0.000675 0.005
                  0.000665 0 0.005
                  -0.00187 0 -0.0025
                  0.00187 0 0.0025
                  0.000665 0 -0.005
                  -0.000665 0 0.005
                  -0.00187 0 0.0025
                  0.00187 0 -0.0025
                  -0.000665 0 -0.005
                  -0.000665 0.000675 0.005
                  -0.000665 0.000675 -0.005
                  -0.000665 0 0
                  0.000665 0 0
                  0.000665 0 0.0025
                  -0.000665 0 0.0025
                  -0.000665 0 -0.0025
                  0.000665 0 -0.0025
                  0 0.000675 -0.005
                  0.000665 0.000675 0.005
                  0.000665 0.000675 -0.005
                  0.000665 0.000675 0.0025
                  0.000665 0.000675 0
                  -0.000665 0.000675 0.0025
                  -0.000665 0.000675 0
                  -0.000665 0.000675 -0.0025
                  0.000665 0.000675 -0.0025
                ]
              }
              coordIndex [
                4, 5, 6, -1, 4, 6, 7, -1, 10, 7
                6, -1, 11, 6, 5, -1, 9, 5, 4, -1
                8, 4, 7, -1, 19, 16, 28, -1, 37, 29
                36, -1, 24, 32, 25, -1, 15, 24, 25, -1
                8, 21, 17, -1, 20, 29, 11, -1, 3, 25
                13, -1, 26, 9, 18, -1, 17, 18, 0, -1
                26, 35, 23, -1, 27, 1, 14, -1, 23, 14
                9, -1, 25, 30, 13, -1, 11, 31, 16, -1
                13, 12, 8, -1, 10, 28, 24, -1, 27, 22
                20, -1, 17, 34, 26, -1, 16, 37, 28, -1
                23, 36, 27, -1, 28, 33, 24, -1, 6, 2
                19, -1, 10, 15, 7, -1, 6, 19, 10, -1
                3, 7, 15, -1, 5, 1, 20, -1, 11, 16
                6, -1, 5, 20, 11, -1, 2, 6, 16, -1
                4, 0, 18, -1, 9, 14, 5, -1, 4, 18
                9, -1, 1, 5, 14, -1, 7, 3, 13, -1
                8, 17, 4, -1, 7, 13, 8, -1, 0, 4
                17, -1, 19, 2, 16, -1, 34, 21, 12, -1
                12, 30, 32, -1, 33, 37, 36, -1, 12, 32
                34, -1, 35, 34, 33, -1, 29, 22, 36, -1
                36, 35, 33, -1, 32, 33, 34, -1, 31, 29
                37, -1, 24, 33, 32, -1, 15, 10, 24, -1
                8, 12, 21, -1, 20, 22, 29, -1, 3, 15
                25, -1, 26, 23, 9, -1, 17, 26, 18, -1
                26, 34, 35, -1, 27, 20, 1, -1, 23, 27
                14, -1, 25, 32, 30, -1, 11, 29, 31, -1
                13, 30, 12, -1, 10, 19, 28, -1, 27, 36
                22, -1, 17, 21, 34, -1, 16, 31, 37, -1
                23, 35, 36, -1, 28, 37, 33, -1
              ]
            }
          }
          geometriesCount 47
        }

        Track {
          translation 0 -0.023 0
          rotation 1 0 0 -1.5707963
          children [
            DEF FRONT_TRACK_WHEEL TrackWheel {
              position 0 0
              radius 0.0145
              children [
                DEF TRACK_WHEEL_BIG Transform {
                  rotation 1 0 0 -1.5707963
                  children [
                    CozmoFrontWheel {}
                  ]
                }
              ]
            }

            DEF REAR_TRACK_WHEEL TrackWheel {
              position -0.048 0.00375
              radius 0.01075
              children [
                DEF TRACK_WHEEL_SMALL Transform {
                  rotation 1 0 0 -1.5707963
                  children [
                    CozmoBackWheel {}
                  ]
                }
              ]
            }
          ]
          name "right track"
          contactMaterial "highfriction"

          %{ if not fields.vizMode.value then }%
          boundingObject USE TRACK_BO
          physics Physics {
          }

          device [
            LinearMotor {
              name "RightWheelMotor"
            }
            PositionSensor {
              name "RightWheelMotorPosSensor"
              resolution 0.001
            }
          ]
          %{ end }%

          animatedGeometry USE ANIMATED_SHAPE
          geometriesCount 47
        }


        DEF LIFT Transform {
          translation -0.041 0 0.0305

          children [
            CozmoUpperShoulder {}

            DEF SHOULDER HingeJoint {
              jointParameters HingeJointParameters {
                axis 0 -1 0
                dampingConstant 1
                position IS liftAngle
                minStop IS liftAngle_lowLimit
                maxStop IS liftAngle_highLimit
              }
              %{ if not fields.vizMode.value then }%
              device [
                RotationalMotor {
                  name "LiftMotor"
                  maxVelocity 30
                  maxTorque 30
                }
                PositionSensor {
                  name "LiftMotorPosSensor"
                  resolution 0.005
                }
              ]
              %{ end }%
              endPoint Solid {
              children [

                #GRIPPER PLATE
                Transform {
                  translation 0.065 0 -0.012
                  children [
                    HingeJoint {
                      jointParameters HingeJointParameters {
                        axis 0 1 0
                      }
                      endPoint DEF SmallFingerGripper Solid {
                        name "GripperPlate"
                        children [

                          Transform {
                            translation 0.004 0 -0.005
                            children [
                              CozmoLifter {}
                            ]
                          }

                          %{ if not fields.vizMode.value then }%
                          Connector {
                            name "gripperConnector"
                            translation 0.0035 0 -0.0145
                            rotation 0 1 0 1.57
                            model "magnetic"
                            distanceTolerance 0.005
                            type "active"
                            isLocked FALSE
                            autoLock TRUE
                            tensileStrength 1
                            shearStrength 1
                          }
                          %{ end }%


                        ] # SmallFingerGripper Children

                        %{ if not fields.vizMode.value then }%
                        boundingObject Transform {
                          translation 0.0 0.0 -0.011
                          children [
                            Shape {
                              geometry Box {
                                #size 0.007 0.036 0.05
                                size 0.007 0.036 0.028
                              }
                            }
                          ]
                        }
                        contactMaterial "cmat_lift"
                        physics Physics {
                          density 1000
                        }
                        %{ end }%
                      }  # SmallFingerGripper Solid
                    } # Hinge Joint
                  ] # Transform children
                } # Transform

                DEF LEFT_LIFT_ARM Transform {
                  translation 0.0434 0.0190 -0.00285
                  children [
                    CozmoUpperLeftArm {}
                  ]
                } # LEFT_LIFT_ARM Transform

                DEF RIGHT_LIFT_ARM Transform {
                  translation 0.0434 -0.0186 -0.0028
                  children [
                    CozmoUpperRightArm {}
                  ]
                } # RIGHT_LIFT_ARM Transform

              ] # endPoint Solid children

              %{ if not fields.vizMode.value then }%
              boundingObject Group {
                children [
                  # Right arm
                  Transform {
                    translation 0 -0.02225 0
                    children [
                      DEF LIFT_ARM_SHAPE Shape {
                        geometry IndexedFaceSet {
                          coord Coordinate {
                            point [
                              0 0.00175 -0.0025
                              0 0.00175 0.0025
                              0.048 0.00175 0.0025
                              0.065 0.00175 -0.0108
                              0.065 0.00175 -0.0158
                              0.048 0.00175 -0.0025
                              0 -0.00175 -0.0025
                              0 -0.00175 0.0025
                              0.048 -0.00175 0.0025
                              0.065 -0.00175 -0.0102
                              0.065 -0.00175 -0.0152
                              0.048 -0.00175 -0.0025
                            ]
                          }
                          coordIndex [
                            0, 1, 2, -1, 0, 2, 5, -1, 2, 3
                            4, -1, 2, 4, 5, -1, 8, 7, 6, -1
                            11, 8, 6, -1, 10, 9, 8, -1, 11, 10
                            8, -1, 1, 7, 8, -1, 1, 8, 2, -1
                            2, 8, 9, -1, 2, 9, 3, -1, 3, 9
                            10, -1, 3, 10, 4, -1, 0, 6, 7, -1
                            0, 7, 1, -1, 11, 6, 0, -1, 11, 0
                            5, -1, 10, 11, 5, -1, 10, 5, 4, -1
                          ]
                          creaseAngle 12
                        }
                      } # DEF LIFT_ARM_SHAPE
                    ]
                  }

                  # Left arm
                  Transform {
                    translation 0 0.02225 0
                    children [
                      USE LIFT_ARM_SHAPE
                    ]
                  }
                ]
              }
              contactMaterial "noFriction"
              physics Physics {
                density 1000
              }
              %{ end }%

              } # endPoint Transform
            } # HingeJoint

            # Lower Set of Arms
            DEF LOWER_LIFT Transform {
              translation 0 0 -0.012

              children [
                CozmoLowerShoulder {}

                # Lower set of arms
                # Note these have no motor and will move with the upper set
                DEF SHOULDER_LOWER HingeJoint {
                  jointParameters HingeJointParameters {
                    axis 0 -1 0
                  }
                  endPoint Solid {
                    children [

                      # Hinge to close mechanical loop back to gripper plate
                      Transform {
                        translation 0.065 0 -0.012
                        children [
                          HingeJoint {
                            jointParameters HingeJointParameters {
                              axis 0 1 0
                            }

                            endPoint SolidReference {
                              solidName "GripperPlate"
                            }
                          }
                        ]
                      }



                      DEF RIGHT_LIFT_ARM_LOWER Transform {
                        translation 0.046 -0.0186 -0.00141
                        children [
                          CozmoLowerRightArm {}
                        ]
                      } # RIGHT_LIFT_ARM_LOWER Transform

                      DEF LEFT_LIFT_ARM_LOWER Transform {
                        translation 0.0459 0.0192 -0.00143
                        children [
                          CozmoLowerLeftArm {}
                        ]
                      } # LEFT_LIFT_ARM_LOWER Transform
                    ] # endPoint Solid Children (lower)


                    %{ if not fields.vizMode.value then }%
                    boundingObject Group {
                      children [
                        # Right arm
                        Transform {
                          translation 0 -0.02225 0
                          children [
                            USE LIFT_ARM_SHAPE
                          ]
                        }

                        # Left arm
                        Transform {
                          translation 0 0.02225 0
                          children [
                            USE LIFT_ARM_SHAPE
                          ]
                        }
                      ]
                    }
                    physics Physics {
                      density 1000
                    }
                    %{ end }%


                  } # endPoint Solid (lower)
                } # DEF SHOULDER_LOWER HingeJoint
              ] # LOWER lift transform children
            } # LOWER lift Transofrm

          ] # LIFT Transform children

          #physics Physics {
          #  density 5000
          #}

        } # Lift Transform

      ] # Wheel RadiusTransform Children

    } # Wheel Radius Transform

  ] # Supervisor children
} # Supervisor

} # PROTO definition
